Workbook
Name _100Excel_BuiltIn_Print_Area_40_1: [1]LMCP_SEF_GT_RD_1!$A$1:$R$32
Name _100Excel_BuiltIn_Print_Area_40_1: [1]LMCP_SEF_GT_RD_1!$A$1:$R$32
Name _100Excel_BuiltIn_Print_Area_40_1: [1]LMCP_SEF_GT_RD_1!$A$1:$R$32
Name _100Excel_BuiltIn_Print_Area_40_1: [1]LMCP_SEF_GT_RD_1!$A$1:$R$32
Name _100Excel_BuiltIn_Print_Area_40_1: [1]LMCP_SEF_GT_RD_1!$A$1:$R$32
Name _102Excel_BuiltIn_Print_Area_44_1: #REF!
Name _102Excel_BuiltIn_Print_Area_44_1: #REF!
Name _102Excel_BuiltIn_Print_Area_44_1: #REF!
Name _102Excel_BuiltIn_Print_Area_44_1: #REF!
Name _102Excel_BuiltIn_Print_Area_44_1: #REF!
Name _102Excel_BuiltIn_Print_Area_44_1: #REF!
Name _102Excel_BuiltIn_Print_Area_44_1: #REF!
Name _103Excel_BuiltIn_Print_Area_40_1: [2]LMCP_SEF_GT_RD_1!$A$1:$R$32
Name _105Excel_BuiltIn_Print_Area_41_1: [1]LMCP_SPF_GT_RD_1!$A$1:$R$32
Name _105Excel_BuiltIn_Print_Area_41_1: [1]LMCP_SPF_GT_RD_1!$A$1:$R$32
Name _105Excel_BuiltIn_Print_Area_41_1: [1]LMCP_SPF_GT_RD_1!$A$1:$R$32
Name _105Excel_BuiltIn_Print_Area_41_1: [1]LMCP_SPF_GT_RD_1!$A$1:$R$32
Name _105Excel_BuiltIn_Print_Area_41_1: [1]LMCP_SPF_GT_RD_1!$A$1:$R$32
Name _106Excel_BuiltIn_Print_Area_45_1: [2]LMCP_AHU_GT_LGM_1!$A$1:$R$32
Name _108Excel_BuiltIn_Print_Area_41_1: [2]LMCP_SPF_GT_RD_1!$A$1:$R$32
Name _10Excel_BuiltIn_Print_Area_100_1: #REF!
Name _10Excel_BuiltIn_Print_Area_100_1: #REF!
Name _10Excel_BuiltIn_Print_Area_100_1: #REF!
Name _10Excel_BuiltIn_Print_Area_100_1: #REF!
Name _10Excel_BuiltIn_Print_Area_100_1: #REF!
Name _10Excel_BuiltIn_Print_Area_100_1: #REF!
Name _10Excel_BuiltIn_Print_Area_100_1: #REF!
Name _10Excel_BuiltIn_Print_Area_14_1: #REF!
Name _10Excel_BuiltIn_Print_Area_14_1: #REF!
Name _10Excel_BuiltIn_Print_Area_14_1: #REF!
Name _10Excel_BuiltIn_Print_Area_14_1: #REF!
Name _10Excel_BuiltIn_Print_Area_14_1: #REF!
Name _10Excel_BuiltIn_Print_Area_14_1: #REF!
Name _10Excel_BuiltIn_Print_Area_14_1: #REF!
Name _110Excel_BuiltIn_Print_Area_42_1: #REF!
Name _110Excel_BuiltIn_Print_Area_42_1: #REF!
Name _110Excel_BuiltIn_Print_Area_42_1: #REF!
Name _110Excel_BuiltIn_Print_Area_42_1: #REF!
Name _110Excel_BuiltIn_Print_Area_42_1: #REF!
Name _110Excel_BuiltIn_Print_Area_46_1: #REF!
Name _110Excel_BuiltIn_Print_Area_46_1: #REF!
Name _110Excel_BuiltIn_Print_Area_46_1: #REF!
Name _110Excel_BuiltIn_Print_Area_46_1: #REF!
Name _110Excel_BuiltIn_Print_Area_46_1: #REF!
Name _110Excel_BuiltIn_Print_Area_46_1: #REF!
Name _110Excel_BuiltIn_Print_Area_46_1: #REF!
Name _113Excel_BuiltIn_Print_Area_42_1: #REF!
Name _113Excel_BuiltIn_Print_Area_42_1: #REF!
Name _113Excel_BuiltIn_Print_Area_42_1: #REF!
Name _113Excel_BuiltIn_Print_Area_42_1: #REF!
Name _113Excel_BuiltIn_Print_Area_42_1: #REF!
Name _113Excel_BuiltIn_Print_Area_42_1: #REF!
Name _113Excel_BuiltIn_Print_Area_42_1: #REF!
Name _114Excel_BuiltIn_Print_Area_47_1: #REF!
Name _114Excel_BuiltIn_Print_Area_47_1: #REF!
Name _114Excel_BuiltIn_Print_Area_47_1: #REF!
Name _114Excel_BuiltIn_Print_Area_47_1: #REF!
Name _114Excel_BuiltIn_Print_Area_47_1: #REF!
Name _114Excel_BuiltIn_Print_Area_47_1: #REF!
Name _114Excel_BuiltIn_Print_Area_47_1: #REF!

Sheet SMDB-1
A2: PROJECT : JBH - TALISE GYM | F2: DETAILS OF CONNECTED LOAD / MAX. DEMAND | N2: LOCATION: 1ST FLOOR ELECT. ROOM GRID 54
A4: SMDB REF : SMDB-1
A6: FED FROM : MDB-2
A8: SR. | B8: CIRCUIT | C8: SP/ | D8: RATING-AMPS | F8: FAULT | G8: PVC/XLPE | I8: ECC | J8: CONNECTED LOAD-KW | N8: KWH METER | R8: REMARKS
A9: NO. | B9: FEEDER | C9: TP | D9: ISO | E9: ACB | F9: DUTY | G9: SWA/PVC | H9: 2/3/4C | I9: SIZE-1C | J9: R-PHASE | K9: Y-PHASE | L9: B-PHASE | M9: TOTAL | N9: 1 Ph | O9: 3 Ph | P9: 3 Ph | Q9: C.T
B10: DB NO. | E10: MCCB | F10: KA | H10: mm2 | I10: mm2 | J10: KW | K10: KW | L10: KW | M10: KW | N10: (1) | O10: (2) | P10: (3) | Q10: 4
B11: INCOMER | C11: TP | D11: 630 | F11: 35 | G11: XLPE/SWA/PVC | H11: 2-4Cx240 | I11: 2-1Cx120 | J11: 130.02 | K11: 127.16 | L11: 119.59 | M11: =SUM(J11:L11) -> 376.77 | Q11: 1
B12: OUTGOING: | N12: REMARKS
A13: 1 | B13: DB-1-N2 | C13: TP | E13: 63 | F13: 32 | G13: XLPE/SWA/PVC | H13: 4Cx35 | I13: 1Cx16 | J13: =('DB-1-N2'!AA45)/1000 -> 9.9 | K13: =('DB-1-N2'!AB45)/1000 -> 8.05 | L13: =('DB-1-N2'!AC45)/1000 -> 6.7 | M13: =SUM(J13:L13) -> 24.65 | N13: NEW
A14: 2 | B14: DB-1-N4 | C14: TP | E14: 63 | F14: 32 | G14: XLPE/SWA/PVC | H14: 4Cx25 | I14: 1Cx16 | J14: 10.95 | K14: 10.42 | L14: 11.07 | M14: =SUM(J14:L14) -> 32.44
A15: 3 | B15: DB-1-N1 | C15: TP | E15: 63 | F15: 32 | H15: 2CX25 | I15: 1Cx16 | J15: 11.23 | K15: 6.33 | L15: 8.75 | M15: =SUM(J15:L15) -> 26.31
A16: 4 | B16: DB-1-27.00 | C16: TP | E16: 63 | F16: 32 | G16: XLPE/SWA/PVC | H16: 4Cx25 | I16: 1Cx16 | J16: 5.6 | K16: 3 | L16: 3.2 | M16: =SUM(J16:L16) -> 11.8
A17: 5 | B17: DB-1-K1 | C17: TP | E17: 100 | F17: 32 | G17: XLPE/SWA/PVC | H17: 4Cx70 | I17: 1Cx35 | J17: 8.81 | K17: 8.06 | L17: 9.56 | M17: =SUM(J17:L17) -> 26.43
A18: 6 | B18: DB-1-23 | C18: TP | E18: 63 | F18: 32 | G18: XLPE/SWA/PVC | H18: 4Cx25 | I18: 1Cx16 | J18: 3.73 | K18: 4.31 | L18: 3.97 | M18: =SUM(J18:L18) -> 12.01
A19: 7 | B19: DB-1-39.00 | C19: SP | E19: 63 | F19: 32 | H19: 2CX25 | I19: 1Cx16 | J19: 0 | M19: =SUM(J19:L19) -> 0 | N19: CANCELLED FROM PHASE 3
A20: 8 | B20: DB-1-40.00 | C20: SP | E20: 63 | F20: 32 | H20: 2CX25 | I20: 1Cx16 | K20: 0 | M20: =SUM(J20:L20) -> 0 | N20: CANCELLED FROM PHASE 3
A21: 9 | B21: DB-1-41.00 | C21: SP | E21: 63 | F21: 32 | H21: 2CX25 | I21: 1Cx16 | L21: 0.25 | M21: =SUM(J21:L21) -> 0.25 | N21: AS PER AS-BUILT LOAD SCHED.
A22: 10 | B22: SMDB-DB-1-N3 | C22: TP | E22: 250 | F22: 32 | G22: XLPE/SWA/PVC | H22: 4Cx240 | I22: 1Cx120 | J22: 27.9 | K22: 34.21 | L22: 24.39 | M22: =SUM(J22:L22) -> 86.5 | N22: REFER TO TALISE GYM
A23: 11 | B23: DB-1-32.00 | C23: SP | E23: 63 | F23: 32 | H23: 2CX25 | I23: 1Cx16 | J23: 4.5 | M23: =SUM(J23:L23) -> 4.5
A24: 12 | B24: DB-1-35.00 | C24: SP | E24: 63 | F24: 32 | H24: 2CX25 | I24: 1Cx16 | K24: 4.5 | M24: =SUM(J24:L24) -> 4.5
A25: 13 | B25: DB-1-38.00 | C25: SP | E25: 63 | F25: 32 | H25: 2CX25 | I25: 1Cx16 | L25: 4.5 | M25: =SUM(J25:L25) -> 4.5
A26: 14 | B26: DB-1-36.00 | C26: SP | E26: 63 | F26: 32 | H26: 2CX25 | I26: 1Cx16 | J26: 4.5 | M26: =SUM(J26:L26) -> 4.5
A27: 15 | B27: DB-1-37.00 | C27: SP | E27: 63 | F27: 32 | H27: 2CX25 | I27: 1Cx16 | K27: 4.5 | M27: =SUM(J27:L27) -> 4.5
A28: 16 | B28: DB-1-35.01 | C28: SP | E28: 63 | F28: 32 | H28: 2CX25 | I28: 1Cx16 | L28: 4.5 | M28: =SUM(J28:L28) -> 4.5
A29: 17 | B29: DB-1-RL | C29: TP | E29: 63 | F29: 32 | G29: XLPE/SWA/PVC | H29: 4Cx25 | I29: 1Cx16 | J29: 6.3 | K29: 4.5 | L29: 6.3 | M29: =SUM(J29:L29) -> 17.1
A30: 18 | B30: SPARE | C30: SP | E30: 63 | F30: 32 | M30: =SUM(J30:L30) -> 0
A31: 19 | B31: DB-1-25.00 | C31: SP | E31: 63 | F31: 32 | H31: 2CX25 | I31: 1CX16 | K31: 0.25 | M31: =SUM(J31:L31) -> 0.25
A32: 20 | B32: DB-1-24.02 | C32: SP | E32: 63 | F32: 32 | H32: 2CX25 | I32: 1CX16 | L32: 4.2 | M32: =SUM(J32:L32) -> 4.2
A33: 21 | B33: CB-1-N4 | C33: SP | E33: 25 | F33: 32 | H33: 2CX10 | I33: 1CX10 | J33: 1.1 | M33: =SUM(J33:L33) -> 1.1
A34: 22 | B34: SPARE | C34: SP | M34: =SUM(J34:L34) -> 0
A35: 23 | B35: SPARE | C35: SP | M35: =SUM(J35:L35) -> 0
A36: 24 | B36: SPARE | C36: TP | M36: =SUM(J36:L36) -> 0
A37: 25 | B37: DB-1-SPA-1 | C37: TP | E37: 100 | F37: 32 | G37: XLPE/SWA/PVC | H37: 4CX35 | I37: 1CX16 | J37: =('1-SPA-1'!W33)/1000 -> 15.786 | K37: =('1-SPA-1'!X33)/1000 -> 15.7875 | L37: =('1-SPA-1'!Y33)/1000 -> 13.417 | M37: =SUM(J37:L37) -> 44.9905 | N37: REPLACE DB-1-42.00
A38: 26 | B38: CB-1-N1 | C38: SP | E38: 25 | F38: 32 | H38: 2CX6 | I38: 1CX6 | J38: 1.16 | M38: =SUM(J38:L38) -> 1.16
A39: 27 | B39: CB-1-N2 | C39: SP | E39: 25 | F39: 32 | H39: 2CX10 | I39: 1CX10 | K39: 0.18 | M39: =SUM(J39:L39) -> 0.18
A40: 28 | B40: CB-1-N3 | C40: SP | E40: 25 | F40: 32 | G40: XLPE/SWA/PVC | H40: 2CX10 | I40: 1CX10 | L40: 1.03 | M40: =SUM(J40:L40) -> 1.03
A41: 29 | B41: DB-1-SPA-2 | C41: TP | E41: 160 | F41: 32 | G41: XLPE/SWA/PVC | H41: 4CX70 | I41: 1CX35 | J41: ='1-SPA2'!V45/1000 -> 22.159333 | K41: ='1-SPA2'!W45/1000 -> 26.273333 | L41: ='1-SPA2'!X45/1000 -> 21.198333 | M41: =SUM(J41:L41) -> 69.631 | N41: REPLACE DN-1-K2
A42: 30 | B42: DB-1-N5 | C42: TP | E42: 63 | F42: 32 | G42: XLPE/SWA/PVC | H42: 4CX25 | I42: 1CX16 | J42: 5.67 | K42: 5.67 | L42: 5.52 | M42: =SUM(J42:L42) -> 16.86
A43: MDB CONNECTED TO : DEWA LV /DB / TRANSF. | F43: TOTAL CONNECTED LOAD PER PHASE | R43: TOTAL
I44: TOTAL | J44: =SUM(J13:J43) -> 139.29533 | K44: =SUM(K13:K43) -> 136.04083 | L44: =SUM(L13:L43) -> 128.55533 | M44: =SUM(M13:M43) -> 403.8915 | R44: =M44 -> 403.8915
...

Sheet DB-1-N2
A1: Project : | B1: JBH - TALISE GYM | H1: LOAD DISTRIBUTION SCHEDULE
A2: DB No: DB-1-N2 | H2: (3-PHASE)
A3: Fed from: SMDB/1
A4: NOTE: | Z4: Location of DB : | AB4: 1ST FLOOR, NORTHWING
A5: Rating of Incomer | B5: Ratg of ELCB | C5: SL. NO. | D5: CIR. No. | E5: MCB Rtg in (A) | F5: CCT wire size mmsq | G5: RCC wire size mmsq | H5: Room / Area | I5: Connected Load / Points | Z5: Watts Each | AA5: Load Per Phase - Watts | AD5: Remarks
N6: LTG | O6: LTG | P6: LTG | Q6: 13A | R6: 13A | S6: 15A | T6: WH | U6: HD | V6: FCU | W6: SPUR | X6: ISOL | Y6: TOTAL
N7: 1 | O7: 2 | P7: 3 | Q7: SO | R7: TSO | S7: SO | AA7: R | AB7: Y | AC7: B
I8: LTG | J8: HO OD | K8: EX. FAN | L8: SH. S/O | M8: 13A SSO | Q8: 200 | R8: 400
A9: 63A TPN ISOLATOR | B9: 63A 100mA 4P | C9: 1 | D9: R1 | E9: 10 | F9: 2.5 | G9: 2.5 | H9: F&B / DIV MANAGER OFFICE LIGHTING | N9: 8 | Z9: 100 | AA9: =Z9*N9 -> 800
C10: 2 | D10: Y1 | E10: 10 | F10: 2.5 | G10: 2.5 | H10: SECRETARY AREA LIGHTING | N10: 8 | Z10: 100 | AB10: =Z10*N10 -> 800
C11: 3 | D11: B1 | E11: 10 | F11: 2.5 | G11: 2.5 | H11: COPY RM/CHIEF ENGR/STORE LIGHTING | N11: 5 | Z11: 100 | AC11: =Z11*N11 -> 500
C12: 4 | D12: R2 | E12: 10 | F12: 2.5 | G12: 2.5 | H12: DIR OF PERSONNEL OFFICE LIGHTING | N12: 7 | Z12: 100 | AA12: =Z12*N12 -> 700
C13: 5 | D13: Y2 | E13: 10 | H13: SPARE | AB13: 0
C14: 6 | D14: B2 | E14: 10 | H14: SPARE | AC14: 0
B15: 63A 100mA 4P | C15: 7 | D15: R3 | E15: 10 | H15: SPARE | AA15: 0
C16: 8 | D16: Y3 | E16: 10 | H16: SPARE | AB16: 0
C17: 9 | D17: B3 | E17: 10 | H17: SPARE | AC17: 0
C18: 10 | D18: R4 | E18: 10 | H18: SPARE | AA18: 0
C19: 11 | D19: Y4 | E19: 10 | F19: 2.5 | G19: 2.5 | H19: LINEN ROOM LIGHTING | N19: 5 | Z19: 50 | AB19: =Z19*N19 -> 250
C20: 12 | D20: B4 | E20: 10 | H20: SPARE | AC20: 0
B21: 63A 30mA 4P | C21: 13 | D21: R5 | E21: 20 | F21: 4 | G21: 4 | H21: FEMALE RELAXATION ROOM | Q21: 1 | R21: 2 | AA21: =(Q21*Q8)+(R21*R8) -> 1000 | AD21: RING
C22: 14 | D22: Y5 | E22: 10 | H22: SPARE | AB22: 0
C23: 15 | D23: B5 | E23: 10 | H23: SPARE | AC23: 0
C24: 16 | D24: R6 | E24: 10 | H24: SPARE | AA24: 0
C25: 17 | D25: Y6 | E25: 10 | H25: SPARE | AB25: 0
C26: 18 | D26: B6 | E26: 10 | H26: SPARE | AC26: 0
B27: 63A 30mA 4P | C27: 19 | D27: R7 | E27: 32 | F27: 4 | G27: 4 | H27: F&B / DIV MNAGER 13A RING | R27: 4 | AA27: =R27*R8 -> 1600
C28: 20 | D28: Y7 | E28: 32 | F28: 4 | G28: 4 | H28: SECRETARY AREA 13A RING | R28: 6 | AB28: =R28*R8 -> 2400
C29: 21 | D29: B7 | E29: 32 | F29: 4 | G29: 4 | H29: COPY RM/CHIEF ENGR/STORE 13A RING | R29: 7 | AC29: =R29*R8 -> 2800
C30: 22 | D30: R8 | E30: 32 | F30: 4 | G30: 4 | H30: DIR OF PERSONNEL OFICE 13A RING | R30: 4 | AA30: =R30*R8 -> 1600
C31: 23 | D31: Y8 | E31: 32 | H31: SPARE | AB31: 0
C32: 24 | D32: B8 | E32: 32 | H32: SPARE | AC32: 0
B33: 63A 30mA 4P | C33: 25 | D33: R9 | E33: 32 | F33: 4 | G33: 4 | H33: FEMALE TREATMENT ROOM 1 | R33: 4 | AA33: =R33*R8 -> 1600 | AD33: RING
C34: 26 | D34: Y9 | E34: 32 | F34: 4 | G34: 4 | H34: FEMALE TREATMENT ROOM 2 | R34: 4 | AB34: =R34*R8 -> 1600 | AD34: RING
C35: 27 | D35: B9 | E35: 32 | F35: 4 | G35: 4 | H35: FEMALE TREATMENT ROOM 3 | R35: 4 | AC35: =R35*R8 -> 1600 | AD35: RING
C36: 28 | D36: R10 | E36: 32 | F36: 4 | G36: 4 | H36: FEMALE TREATMENT ROOM 4 | R36: 4 | AA36: =R36*R8 -> 1600 | AD36: RING
C37: 29 | D37: Y10 | E37: 32 | F37: 4 | G37: 4 | H37: FEMALE TREATMENT ROOM 5 | R37: 4 | AB37: =R37*R8 -> 1600 | AD37: RING
C38: 30 | D38: B10 | E38: 32 | F38: 4 | G38: 4 | H38: FEMALE PREP | Q38: 1 | R38: 2 | AC38: =(Q38*Q8)+(R38*R8) -> 1000 | AD38: RING
B39: 63A 100mA 4P | C39: 31 | D39: R11 | E39: 20 | F39: 4 | G39: 4 | H39: F@B/DIV MANAGER/DIR PER FCU | V39: 3 | Z39: 200 | AA39: =Z39*V39 -> 600
C40: 32 | D40: Y11 | E40: 20 | F40: 4 | G40: 4 | H40: SECRETARY AREA FCU | V40: 2 | Z40: 200 | AB40: =Z40*V40 -> 400
...

Sheet 1-SPA2
A1: Project : | B1: JBH - TALISE GYM | H1: LOAD DISTRIBUTION SCHEDULE
A2: DB No: DB-1-SPA2 | H2: (3-PHASE)
A3: Fed from: SMDB/1
A4: NOTE: NEW DB, TO REPLACE DB-1-K2 | U4: Location of DB : | W4: 1ST FLOOR, TECH ROOM2
A5: Rating of Incomer | B5: Ratg of ELCB | C5: SL. NO. | D5: CIR. No. | E5: MCB Rtg in (A) | F5: CCT wire size mmsq | G5: RCC wire size mmsq | H5: Room / Area | U5: Watts Each | V5: Load Per Phase - Watts | Y5: Remarks
I6: LTG | J6: LTG | K6: LTG | L6: 13A | M6: 13A | N6: 15A | O6: WH | P6: HD | Q6: FCU | R6: SPUR | S6: ISOL | T6: TOTAL
I7: 1 | J7: 2 | K7: 3 | L7: SO | M7: TSO | N7: SO | V7: R | W7: Y | X7: B
L8: 200 | M8: 400
A9: 160A TPN ISOLATOR | B9: 40A 100mA 4P | C9: 1 | D9: R1 | E9: 63 | F9: 16 | G9: 16 | H9: DB - 1 - SPA3 | V9: ='1-SPA-3'!W33 -> 2476
C10: 2 | D10: Y1 | W10: ='1-SPA-3'!X33 -> 2370
C11: 3 | D11: B1 | X11: ='1-SPA-3'!Y33 -> 3445
B12: 40A 30mA 4P | C12: 4 | D12: R2 | E12: 20 | F12: 4 | G12: 4 | H12: WC-SENSORY FLUSH | R12: 3 | U12: 50 | V12: =U12*R12 -> 150
C13: 5 | D13: Y2 | E13: 20 | F13: 4 | G13: 4 | H13: RELAXATION ROOM | M13: 2 | W13: =M13*M8 -> 800
C14: 6 | D14: B2 | E14: 20 | F14: 4 | G14: 4 | H14: RELAXATION ROOM | M14: 1 | X14: =M14*M8 -> 400
B15: 40A 30mA 4P | C15: 7 | D15: R3 | E15: 20 | F15: 4 | G15: 4 | H15: COUPLE SAUNA | S15: 1 | U15: 9000 | V15: =U15/3 -> 3000
C16: 8 | D16: Y3 | W16: =U15/3 -> 3000
C17: 9 | D17: B3 | X17: =U15/3 -> 3000
B18: 40A 30mA 4P | C18: 10 | D18: R4 | E18: 20 | F18: 4 | G18: 4 | H18: COUPLE STEAM GENERATOR | S18: 1 | U18: 4900 | V18: =U18/3 -> 1633.3333
C19: 11 | D19: Y4 | W19: =U18/3 -> 1633.3333
C20: 12 | D20: B4 | X20: =U18/3 -> 1633.3333
B21: 40A 30mA 4P | C21: 13 | D21: R5 | E21: 20 | F21: 4 | G21: 4 | H21: MALE SAUNA | S21: 1 | U21: 9000 | V21: =U21/3 -> 3000
C22: 14 | D22: Y5 | W22: =U21/3 -> 3000
C23: 15 | D23: B5 | X23: =U21/3 -> 3000
B24: 40A 30mA 4P | C24: 16 | D24: R6 | E24: 20 | F24: 4 | G24: 4 | H24: FM. ICE FOUNTAIN | S24: 1 | U24: 800 | V24: =U24*S24 -> 800
C25: 17 | D25: Y6 | E25: 20 | F25: 4 | G25: 4 | H25: FM. HEATED BENCH | S25: 1 | U25: 1220 | W25: =U25*S25 -> 1220
C26: 18 | D26: B6 | E26: 20 | F26: 4 | G26: 4 | H26: M. HEATED BENCH | S26: 1 | U26: 1220 | X26: =U26*S26 -> 1220
B27: 40A 30mA 4P | C27: 19 | D27: R7 | E27: 20 | F27: 4 | G27: 4 | H27: M. ICE FOUNTAIN | S27: 1 | U27: 800 | V27: =U27*S27 -> 800
C28: 20 | D28: Y7 | E28: 20 | F28: 4 | G28: 4 | H28: FEMALE EXPERIENCE SHOWER | S28: 1 | U28: 100 | W28: =U28*S28 -> 100
C29: 21 | D29: B7 | E29: 20 | F29: 4 | G29: 4 | H29: MALE EXPERIENCE SHOWER | S29: 1 | U29: 100 | X29: =U29*S29 -> 100
B30: 40A 30mA 4P | C30: 22 | D30: R8 | E30: 20 | F30: 4 | G30: 4 | H30: COUPLE HAMMAM | S30: 1 | U30: 1500 | V30: =U30*S30 -> 1500
C31: 23 | D31: Y8 | W31: 0
C32: 24 | D32: B8 | X32: 0
B33: 40A 30mA 4P | C33: 25 | D33: R9 | V33: 0
C34: 26 | D34: Y9 | E34: 40 | F34: 10 | G34: 10 | H34: WHIRLPOOL | U34: 5750 | W34: =U34 -> 5750
C35: 27 | D35: B9 | X35: =M35*M8 -> 0
B36: 40A 30mA 4P | C36: 28 | D36: R10 | E36: 20 | F36: 4 | G36: 4 | H36: TECH. ROOM 1 | L36: 1 | M36: 1 | V36: =L36*L8+M36*M8 -> 600
C37: 29 | D37: Y10 | E37: 20 | F37: 4 | G37: 4 | H37: TECH. ROOM 2 | L37: 1 | W37: =L37*L8 -> 200
C38: 30 | D38: B10 | E38: 20 | F38: 4 | G38: 4 | H38: MALE EXPERIENCE SHOWER | L38: 1 | X38: =L38*L8 -> 200
B39: 40A 30mA 4P | C39: 31 | D39: R11 | E39: 40 | F39: 10 | G39: 10 | H39: FEMALE STEAM GENERATOR | S39: 1 | U39: 12300 | V39: =U39/3 -> 4100
C40: 32 | D40: Y11 | W40: =U39/3 -> 4100
...

Sheet 1-SPA-1
A1: Project : | B1: JBH - TALISE GYM | H1: LOAD DISTRIBUTION SCHEDULE
A2: DB No: DB-1-SPA-1 | H2: (3-PHASE)
A3: Fed from: SMDB/1
A4: NOTE: | V4: Location of DB : | X4: 1ST FLOOR, TECH ROOM2
A5: Rating of Incomer | B5: Ratg of ELCB | C5: SL. NO. | D5: CIR. No. | E5: MCB Rtg in (A) | F5: CCT wire size mmsq | G5: RCC wire size mmsq | H5: Room / Area | V5: Watts Each | W5: Load Per Phase - Watts | Z5: Remarks
I6: LTG | J6: LTG | K6: LTG | L6: 13A | M6: 13A | N6: 15A | O6: SH | P6: WH | Q6: HD | R6: FCU | S6: SPUR | T6: ISOL | U6: TOTAL
I7: 1 | J7: 2 | K7: 3 | L7: SO | M7: TSO | N7: SO | W7: R | X7: Y | Y7: B
L8: 200 | M8: 400 | O8: 100 | Q8: 1500
A9: 100A TPN ISOLATOR | B9: 63A 30mA 4P | C9: 1 | D9: R1 | E9: 63 | F9: 16 | G9: 16 | H9: DB-SP-LL | W9: ='SP-LL'!AF39 -> 8262
C10: 2 | D10: Y1 | X10: ='SP-LL'!AG39 -> 9125.5
C11: 3 | D11: B1 | Y11: ='SP-LL'!AH39 -> 8155
C12: 4 | D12: R2 | W12: =V12*S12 -> 0
C13: 5 | D13: Y2 | X13: =M13*M8 -> 0
C14: 6 | D14: B2 | Y14: 0
B15: 40A 30mA 4P | C15: 7 | D15: R3 | E15: 20 | F15: 4 | G15: 4 | H15: FEMALE TREATMENT CORRIDOR | L15: 3 | W15: =L15*L8 -> 600
C16: 8 | D16: Y3 | E16: 20 | F16: 4 | G16: 4 | H16: MALE CORRIDOR | L16: 5 | X16: =L16*L8 -> 1000
C17: 9 | D17: B3 | E17: 20 | F17: 4 | G17: 4 | H17: MALE TREATMENT CORRIDOR | L17: 3 | Y17: =L17*L8 -> 600
C18: 10 | D18: R4 | E18: 32 | F18: 4 | G18: 4 | H18: COUPLES TREATMENT ROOM | M18: 5 | W18: =M18*M8 -> 2000 | Z18: Ring
C19: 11 | D19: Y4 | E19: 32 | F19: 4 | G19: 4 | H19: MALE TREATMENT ROOM-4 | M19: 4 | X19: =M19*M8+O19*O8 -> 1600 | Z19: Ring
C20: 12 | D20: B4 | E20: 32 | F20: 4 | G20: 4 | H20: MALE TREATMENT ROOM-3 | M20: 4 | Y20: =M20*M8+O20*O8 -> 1600 | Z20: Ring
B21: 40A 30mA 4P | C21: 13 | D21: R5 | E21: 32 | F21: 4 | G21: 4 | H21: MALE TREATMENT ROOM-2 | M21: 4 | W21: =M21*M8+O21*O8 -> 1600 | Z21: Ring
C22: 14 | D22: Y5 | E22: 32 | F22: 4 | G22: 4 | H22: MALE TREATMENT ROOM-1 | M22: 4 | X22: =M22*M8+O22*O8 -> 1600 | Z22: Ring
C23: 15 | D23: B5 | E23: 20 | F23: 4 | G23: 4 | H23: MALE PREP. | L23: 1 | M23: 1 | Y23: =(L23*L8)+(M23*M8) -> 600
C24: 16 | D24: R6 | E24: 20 | F24: 4 | G24: 4 | H24: FEMALE CHANGING AREA | O24: 1 | Q24: 1 | W24: =Q24*Q8+O24*O8 -> 1600
C25: 17 | D25: Y6 | E25: 20 | F25: 4 | G25: 4 | H25: COUPLES CHANGING AREA | O25: 1 | Q25: 1 | X25: =Q25*Q8+O25*O8 -> 1600
C26: 18 | D26: B6 | E26: 20 | F26: 4 | G26: 4 | H26: MALE CHANGING AREA | O26: 1 | Q26: 1 | Y26: =Q26*Q8+O26*O8 -> 1600
B27: 40A 100mA 4P | C27: 19 | D27: R7 | E27: 20 | F27: 4 | G27: 4 | H27: CORRIDOR,FCU | R27: 1 | V27: 862 | W27: =V27*R27 -> 862
C28: 20 | D28: Y7 | E28: 20 | F28: 4 | G28: 4 | H28: CORRIDOR,FCU | R28: 1 | V28: 862 | X28: =V28*R28 -> 862
C29: 21 | D29: B7 | E29: 20 | F29: 4 | G29: 4 | H29: CORRIDOR,FCU | R29: 1 | V29: 862 | Y29: =V29*R29 -> 862
C30: 22 | D30: R8 | E30: 20 | F30: 4 | G30: 4 | H30: CORRIDOR,FCU | R30: 1 | V30: 862 | W30: =V30*R30 -> 862
C31: 23 | D31: Y8
C32: 24 | D32: B8
S33: TOTAL CONNECTED LOAD | W33: =SUM(W9:W32) -> 15786 | X33: =SUM(X9:X32) -> 15787.5 | Y33: =SUM(Y9:Y32) -> 13417 | Z33: =SUM(W33:Y33) -> 44990.5
S34: TOTAL CONNECTED LOAD (PF=0.8) | W34: =W33/0.8 -> 19732.5 | X34: =X33/0.8 -> 19734.375 | Y34: =Y33/0.8 -> 16771.25 | Z34: =SUM(W34:Y34) -> 56238.125
S35: DIVERSITY FACTOR | W35: 0.7
S36: TOTAL DIVERSITY LOAD | W36: =(W35*Z34)/1000 -> 39.366687 | Y36: KW
A37: CABLE SIZE : | B37: 4C 35 mm² Cu/XLPE/SWA/PVC + 1C 16 mm² Cu/PVC ECC
A38: W/H:WATER HEATER , WM: WASHING MACHINE, FCU - FAN COIL UNIT, H/D- HAND DRYER

Sheet SP-LL
A1: Project : | B1: JBH - TALISE GYM | H1: LOAD DISTRIBUTION SCHEDULE
A2: DB No: DB-SP-LL | H2: (3-PHASE)
A3: Fed from: DB-1-SPA1
A4: NOTE: | AE4: Location of DB : | AG4: 1ST FLOOR, TECH ROOM2
A5: Rating of Incomer | B5: Ratg of ELCB | C5: SL. NO. | D5: CIR. No. | E5: MCB Rtg in (A) | F5: CCT wire size mmsq | G5: RCC wire size mmsq | H5: Room / Area | I5: Connected Load / Points | AE5: Watts Each | AF5: Load Per Phase - Watts | AI5: Remarks
N6: LTG | O6: LTG | P6: LTG | Q6: LTG | R6: LTG | S6: LTG | T6: LTG | U6: SPA LIGHTING | Z6: LTG | AA6: JB | AB6: SH | AC6: OTHERS | AD6: TOTAL
N7: 101 | O7: 102 | P7: 601 | Q7: 602 | R7: 701 | S7: 702 | T7: 703 | U7: CL | V7: UB | W7: SF | X7: SL | Y7: STRIP | Z7: 704 | AB7: S/O | AF7: R | AG7: Y | AH7: B
I8: LTG | J8: HO OD | K8: EX. FAN | L8: SH. S/O | M8: 13A SSO | N8: 15 | O8: 15 | P8: 20 | Q8: 50 | R8: 50 | S8: 50 | T8: 50 | U8: 20 | V8: 15 | W8: 100 | X8: 20 | Y8: 15 | Z8: 20 | AA8: 200 | AB8: 50 | AC8: 50
A9: 63A TPN ISOLATOR | B9: 40A 100mA 4P | C9: 1 | D9: R1 | E9: 16 | F9: 2.5 | G9: 2.5 | H9: FEMALE WET AREA, STEAM ROOM | N9: 7.5 | O9: =4.1+3.3+3+3 -> 13.4 | R9: 3 | U9: 2 | V9: 3.3 | AF9: =SUM($N9*$N$8,$O9*$O$8,$P9*$P$8,$Q9*$Q$8,$R9*$R$8,$S9*$S$8,$T9*$T$8,$U9*$U$8,$V9*$V$8,$W9*$W$8,$X9*$X$8,$Y9*$Y$8,$Z9*$Z$8,$AA9*$AA$8,$AB9*$AB$8) -> 553
C10: 2 | D10: Y1 | E10: 10 | F10: 2.5 | G10: 2.5 | H10: FEMALE CHANGING AREA | N10: =5.4+5.9+5.5+1.4+1.2+1.2+1.2 -> 21.8 | O10: 1.2 | R10: 5 | S10: =1+2+1+1+2+2+2 -> 11 | AA10: 3 | AC10: 4 | AG10: =SUM($N10*$N$8,$O10*$O$8,$P10*$P$8,$Q10*$Q$8,$R10*$R$8,$S10*$S$8,$T10*$T$8,$U10*$U$8,$V10*$V$8,$W10*$W$8,$X10*$X$8,$Y10*$Y$8,$Z10*$Z$8,$AA10*$AA$8,$AB10*$AB$8) -> 1745
C11: 3 | D11: B1 | E11: 16 | F11: 2.5 | G11: 2.5 | H11: FEMALE CORRIDOR | N11: =8.4+7.6 -> 16 | R11: =30+8 -> 38 | S11: =7+5 -> 12 | Z11: =1+1 -> 2 | AA11: 2 | AH11: =SUM($N11*$N$8,$O11*$O$8,$P11*$P$8,$Q11*$Q$8,$R11*$R$8,$S11*$S$8,$T11*$T$8,$U11*$U$8,$V11*$V$8,$W11*$W$8,$X11*$X$8,$Y11*$Y$8,$Z11*$Z$8,$AA11*$AA$8,$AB11*$AB$8) -> 3180
C12: 4 | D12: R2 | E12: 10 | F12: 2.5 | G12: 2.5 | H12: COUPLES TREATMENT ROOM | N12: =3.7+11.7+3 -> 18.4 | O12: =7.1+3.3+0.9+0.9+0.9 -> 13.1 | R12: 7 | AA12: 1 | AF12: =SUM($N12*$N$8,$O12*$O$8,$P12*$P$8,$Q12*$Q$8,$R12*$R$8,$S12*$S$8,$T12*$T$8,$U12*$U$8,$V12*$V$8,$W12*$W$8,$X12*$X$8,$Y12*$Y$8,$Z12*$Z$8,$AA12*$AA$8,$AB12*$AB$8) -> 1022.5
C13: 5 | D13: Y2 | E13: 10 | F13: 2.5 | G13: 2.5 | H13: COUPLES CHANGING ROOM | N13: =1.4+1.4+8.1+1.4+1.4 -> 13.7 | O13: =1.3+1.3 -> 2.6 | R13: 4 | S13: 2 | AA13: 2 | AG13: =SUM($N13*$N$8,$O13*$O$8,$P13*$P$8,$Q13*$Q$8,$R13*$R$8,$S13*$S$8,$T13*$T$8,$U13*$U$8,$V13*$V$8,$W13*$W$8,$X13*$X$8,$Y13*$Y$8,$Z13*$Z$8,$AA13*$AA$8,$AB13*$AB$8) -> 944.5
C14: 6 | D14: B2 | E14: 10 | F14: 2.5 | G14: 2.5 | H14: COUPLE HAMMAM, STEAM ROOM | O14: =3.4+3.5+3+3+1.9+1.9 -> 16.7 | U14: 8 | X14: =5+2 -> 7 | AH14: =SUM($N14*$N$8,$O14*$O$8,$P14*$P$8,$Q14*$Q$8,$R14*$R$8,$S14*$S$8,$T14*$T$8,$U14*$U$8,$V14*$V$8,$W14*$W$8,$X14*$X$8,$Y14*$Y$8,$Z14*$Z$8,$AA14*$AA$8,$AB14*$AB$8) -> 550.5
B15: 40A 100mA 4P | C15: 7 | D15: R3 | E15: 10 | F15: 2.5 | G15: 2.5 | H15: SPA ENTRY CORRIDOR | N15: 17.1 | R15: 6 | S15: 3 | Y15: 3.5 | AA15: 2 | AC15: 4 | AF15: =SUM($N15*$N$8,$O15*$O$8,$P15*$P$8,$Q15*$Q$8,$R15*$R$8,$S15*$S$8,$T15*$T$8,$U15*$U$8,$V15*$V$8,$W15*$W$8,$X15*$X$8,$Y15*$Y$8,$Z15*$Z$8,$AA15*$AA$8,$AB15*$AB$8,AC15*AC8) -> 1359
C16: 8 | D16: Y3 | E16: 10 | F16: 2.5 | G16: 2.5 | H16: CORRIDOR | R16: 16 | AG16: =SUM(N16*N8,R16*R8) -> 800
C17: 9 | D17: B3 | E17: 10 | F17: 2.5 | G17: 2.5 | H17: MALE WET AREA, SAUNA, STEAM | N17: =3.6+1.8 -> 5.4 | O17: =7.3+1+2.2+2.1 -> 12.6 | R17: 5 | U17: 4 | AH17: =SUM($N17*$N$8,$O17*$O$8,$P17*$P$8,$Q17*$Q$8,$R17*$R$8,$S17*$S$8,$T17*$T$8,$U17*$U$8,$V17*$V$8,$W17*$W$8,$X17*$X$8,$Y17*$Y$8,$Z17*$Z$8,$AA17*$AA$8,$AB17*$AB$8) -> 600
C18: 10 | D18: R4 | E18: 10 | F18: 2.5 | G18: 2.5 | H18: MALE WC, STEAM ROOM | N18: =1.2+1.2 -> 2.4 | O18: =2.3+1.2+3.7 -> 7.2 | R18: 1 | S18: 1 | U18: 2 | AA18: 1 | AC18: 2 | AF18: =SUM($N18*$N$8,$O18*$O$8,$P18*$P$8,$Q18*$Q$8,$R18*$R$8,$S18*$S$8,$T18*$T$8,$U18*$U$8,$V18*$V$8,$W18*$W$8,$X18*$X$8,$Y18*$Y$8,$Z18*$Z$8,$AA18*$AA$8,$AB18*$AB$8) -> 484
C19: 11 | D19: Y4 | E19: 10 | F19: 2.5 | G19: 2.5 | H19: MALE CHANGING AREA , SHO | N19: =1.4+6.5+1.7+5.5+1.2+1.2+1.2 -> 18.7 | R19: 4 | S19: =2+1+1+1+2+2+2 -> 11 | AA19: 3 | AC19: 2 | AG19: =SUM($N19*$N$8,$O19*$O$8,$P19*$P$8,$Q19*$Q$8,$R19*$R$8,$S19*$S$8,$T19*$T$8,$U19*$U$8,$V19*$V$8,$W19*$W$8,$X19*$X$8,$Y19*$Y$8,$Z19*$Z$8,$AA19*$AA$8,$AB19*$AB$8) -> 1630.5
C20: 12 | D20: B4 | E20: 10 | F20: 2.5 | G20: 2.5 | H20: B.O.H LIFT LOBBY, CLEAN LINEN STORAGE, MALE CORRIDOR | N20: =4.8+6 -> 10.8 | Q20: 1 | R20: =4+2 -> 6 | S20: 3 | Z20: 3 | AH20: =SUM($N20*$N$8,$O20*$O$8,$P20*$P$8,$Q20*$Q$8,$R20*$R$8,$S20*$S$8,$T20*$T$8,$U20*$U$8,$V20*$V$8,$W20*$W$8,$X20*$X$8,$Y20*$Y$8,$Z20*$Z$8,$AA20*$AA$8,$AB20*$AB$8) -> 722
B21: 40A 100mA 4P | C21: 13 | D21: R5 | E21: 10 | F21: 2.5 | G21: 2.5 | H21: MALE CORRIDOR | R21: 8 | AF21: =SUM($N21*$N$8,$O21*$O$8,$P21*$P$8,$Q21*$Q$8,$R21*$R$8,$S21*$S$8,$T21*$T$8,$U21*$U$8,$V21*$V$8,$W21*$W$8,$X21*$X$8,$Y21*$Y$8,$Z21*$Z$8,$AA21*$AA$8,$AB21*$AB$8) -> 400
C22: 14 | D22: Y5 | E22: 10 | F22: 2.5 | G22: 2.5 | H22: MALE CORRIDOR | R22: 12 | AG22: =SUM($N22*$N$8,$O22*$O$8,$P22*$P$8,$Q22*$Q$8,$R22*$R$8,$S22*$S$8,$T22*$T$8,$U22*$U$8,$V22*$V$8,$W22*$W$8,$X22*$X$8,$Y22*$Y$8,$Z22*$Z$8,$AA22*$AA$8,$AB22*$AB$8) -> 600
C23: 15 | D23: B5 | E23: 10 | F23: 2.5 | G23: 2.5 | H23: MALE CORRIDOR | R23: 14 | AH23: =SUM($N23*$N$8,$O23*$O$8,$P23*$P$8,$Q23*$Q$8,$R23*$R$8,$S23*$S$8,$T23*$T$8,$U23*$U$8,$V23*$V$8,$W23*$W$8,$X23*$X$8,$Y23*$Y$8,$Z23*$Z$8,$AA23*$AA$8,$AB23*$AB$8) -> 700
C24: 16 | D24: R6 | E24: 10 | F24: 2.5 | G24: 2.5 | H24: MALE TREATMENT CORRIDOR | N24: 10.1 | S24: 7 | AB24: 4 | AF24: =SUM($N24*$N$8,$O24*$O$8,$P24*$P$8,$Q24*$Q$8,$R24*$R$8,$S24*$S$8,$T24*$T$8,$U24*$U$8,$V24*$V$8,$W24*$W$8,$X24*$X$8,$Y24*$Y$8,$Z24*$Z$8,$AA24*$AA$8,$AB24*$AB$8) -> 701.5
C25: 17 | D25: Y6 | E25: 10 | F25: 2.5 | G25: 2.5 | H25: MALE TREATMENT ROOM 4 | N25: =1.1+9 -> 10.1 | R25: 5 | AG25: =SUM($N25*$N$8,$O25*$O$8,$P25*$P$8,$Q25*$Q$8,$R25*$R$8,$S25*$S$8,$T25*$T$8,$U25*$U$8,$V25*$V$8,$W25*$W$8,$X25*$X$8,$Y25*$Y$8,$Z25*$Z$8,$AA25*$AA$8,$AB25*$AB$8) -> 401.5
C26: 18 | D26: B6 | E26: 10 | F26: 2.5 | G26: 2.5 | H26: MALE TREATMENT ROOM 1&2 | N26: =9+2.5+9+1.2+1.2+1.2 -> 24.1 | R26: =4+5 -> 9 | S26: =1+2+2 -> 5 | AH26: =SUM($N26*$N$8,$O26*$O$8,$P26*$P$8,$Q26*$Q$8,$R26*$R$8,$S26*$S$8,$T26*$T$8,$U26*$U$8,$V26*$V$8,$W26*$W$8,$X26*$X$8,$Y26*$Y$8,$Z26*$Z$8,$AA26*$AA$8,$AB26*$AB$8) -> 1061.5
B27: 40A 100mA 4P | C27: 19 | D27: R7 | E27: 10 | F27: 2.5 | G27: 2.5 | H27: MALE TREATMENT ROOM 3 | N27: =9+1.5 -> 10.5 | R27: 4 | S27: 1 | AF27: =SUM($N27*$N$8,$O27*$O$8,$P27*$P$8,$Q27*$Q$8,$R27*$R$8,$S27*$S$8,$T27*$T$8,$U27*$U$8,$V27*$V$8,$W27*$W$8,$X27*$X$8,$Y27*$Y$8,$Z27*$Z$8,$AA27*$AA$8,$AB27*$AB$8) -> 407.5
C28: 20 | D28: Y7 | E28: 10 | F28: 2.5 | G28: 2.5 | H28: MALE RELAXATION ROOM | N28: 11.2 | R28: 4 | AG28: =SUM($N28*$N$8,$O28*$O$8,$P28*$P$8,$Q28*$Q$8,$R28*$R$8,$S28*$S$8,$T28*$T$8,$U28*$U$8,$V28*$V$8,$W28*$W$8,$X28*$X$8,$Y28*$Y$8,$Z28*$Z$8,$AA28*$AA$8,$AB28*$AB$8) -> 368
C29: 21 | D29: B7 | E29: 10 | F29: 2.5 | G29: 2.5 | H29: TECH ROOM 1 | W29: 2 | AH29: =SUM($N29*$N$8,$O29*$O$8,$P29*$P$8,$Q29*$Q$8,$R29*$R$8,$S29*$S$8,$T29*$T$8,$U29*$U$8,$V29*$V$8,$W29*$W$8,$X29*$X$8,$Y29*$Y$8,$Z29*$Z$8,$AA29*$AA$8,$AB29*$AB$8) -> 200
C30: 22 | D30: R8 | E30: 10 | F30: 2.5 | G30: 2.5 | H30: TECH ROOM 2 | W30: 2 | AF30: =SUM($N30*$N$8,$O30*$O$8,$P30*$P$8,$Q30*$Q$8,$R30*$R$8,$S30*$S$8,$T30*$T$8,$U30*$U$8,$V30*$V$8,$W30*$W$8,$X30*$X$8,$Y30*$Y$8,$Z30*$Z$8,$AA30*$AA$8,$AB30*$AB$8) -> 200
C31: 23 | D31: Y8 | E31: 10 | F31: 2.5 | G31: 2.5 | H31: FEMALE TREATMENT 1&2 , SHOWER | N31: =16.8+9+1.8+1.2+1.2 -> 30 | O31: 1.2 | R31: =6+4 -> 10 | S31: =1+1+2+2 -> 6 | AG31: =SUM($N31*$N$8,$O31*$O$8,$P31*$P$8,$Q31*$Q$8,$R31*$R$8,$S31*$S$8,$T31*$T$8,$U31*$U$8,$V31*$V$8,$W31*$W$8,$X31*$X$8,$Y31*$Y$8,$Z31*$Z$8,$AA31*$AA$8,$AB31*$AB$8) -> 1268
C32: 24 | D32: B8 | E32: 10 | F32: 2.5 | G32: 2.5 | H32: FEMALE TREATMENT 3&4 | N32: =9.1+0.8+1.9+2.2+9.6+1.8 -> 25.4 | R32: =4+6 -> 10 | S32: =1+1 -> 2 | AH32: =SUM($N32*$N$8,$O32*$O$8,$P32*$P$8,$Q32*$Q$8,$R32*$R$8,$S32*$S$8,$T32*$T$8,$U32*$U$8,$V32*$V$8,$W32*$W$8,$X32*$X$8,$Y32*$Y$8,$Z32*$Z$8,$AA32*$AA$8,$AB32*$AB$8) -> 981
B33: 40A 100mA 4P | C33: 25 | D33: R9 | E33: 10 | F33: 2.5 | G33: 2.5 | H33: FEMALE TREATMENT 5 | N33: =1.6+9.7+1 -> 12.3 | R33: 6 | S33: 1 | AF33: =SUM($N33*$N$8,$O33*$O$8,$P33*$P$8,$Q33*$Q$8,$R33*$R$8,$S33*$S$8,$T33*$T$8,$U33*$U$8,$V33*$V$8,$W33*$W$8,$X33*$X$8,$Y33*$Y$8,$Z33*$Z$8,$AA33*$AA$8,$AB33*$AB$8) -> 534.5
C34: 26 | D34: Y9 | E34: 10 | F34: 2.5 | G34: 2.5 | H34: FEMALE RELAXATION ROOM | N34: =9.9+1.3 -> 11.2 | R34: 4 | AG34: =SUM($N34*$N$8,$O34*$O$8,$P34*$P$8,$Q34*$Q$8,$R34*$R$8,$S34*$S$8,$T34*$T$8,$U34*$U$8,$V34*$V$8,$W34*$W$8,$X34*$X$8,$Y34*$Y$8,$Z34*$Z$8,$AA34*$AA$8,$AB34*$AB$8) -> 368
C35: 27 | D35: B9 | E35: 10 | F35: 2.5 | G35: 2.5 | H35: FEMALE PREP | Z35: 4 | AH35: =SUM($N35*$N$8,$O35*$O$8,$P35*$P$8,$Q35*$Q$8,$R35*$R$8,$S35*$S$8,$T35*$T$8,$U35*$U$8,$V35*$V$8,$W35*$W$8,$X35*$X$8,$Y35*$Y$8,$Z35*$Z$8,$AA35*$AA$8,$AB35*$AB$8) -> 80
C36: 28 | D36: R10 | E36: 10 | F36: 2.5 | G36: 2.5 | H36: CORRIDOR | AA36: 13 | AF36: =SUM($N36*$N$8,$O36*$O$8,$P36*$P$8,$Q36*$Q$8,$R36*$R$8,$S36*$S$8,$T36*$T$8,$U36*$U$8,$V36*$V$8,$W36*$W$8,$X36*$X$8,$Y36*$Y$8,$Z36*$Z$8,$AA36*$AA$8,$AB36*$AB$8) -> 2600
C37: 29 | D37: Y10 | E37: 10 | F37: 2.5 | G37: 2.5 | H37: FEMALE TREATMENT CORRIDOR | AA37: 5 | AG37: =SUM($N37*$N$8,$O37*$O$8,$P37*$P$8,$Q37*$Q$8,$R37*$R$8,$S37*$S$8,$T37*$T$8,$U37*$U$8,$V37*$V$8,$W37*$W$8,$X37*$X$8,$Y37*$Y$8,$Z37*$Z$8,$AA37*$AA$8,$AB37*$AB$8) -> 1000
C38: 30 | D38: B10 | E38: 10 | F38: 2.5 | G38: 2.5 | H38: MALE PREP | AA38: 2 | AE38: 40 | AH38: =AE38*AA38 -> 80
AA39: TOTAL CONNECTED LOAD | AF39: =SUM(AF9:AF38) -> 8262 | AG39: =SUM(AG9:AG38) -> 9125.5 | AH39: =SUM(AH9:AH38) -> 8155 | AI39: =SUM(AF39:AH39) -> 25542.5
AA40: TOTAL CONNECTED LOAD (PF=0.8) | AF40: =AF39/0.8 -> 10327.5 | AG40: =AG39/0.8 -> 11406.875 | AH40: =AH39/0.8 -> 10193.75 | AI40: =SUM(AF40:AH40) -> 31928.125
...

Sheet 1-SPA-3
A1: Project : | B1: JBH - TALISE GYM | H1: LOAD DISTRIBUTION SCHEDULE
A2: DB No: DB-1-SPA-3 | H2: (3-PHASE)
A3: Fed from: DB-1-SPA2
A4: NOTE: | V4: Location of DB : | X4: 1ST FLOOR, RETAIL STORAGE
A5: Rating of Incomer | B5: Ratg of ELCB | C5: SL. NO. | D5: CIR. No. | E5: MCB Rtg in (A) | F5: CCT wire size mmsq | G5: RCC wire size mmsq | H5: Room / Area | V5: Watts Each | W5: Load Per Phase - Watts | Z5: Remarks
I6: LTG | J6: LTG | K6: LTG | L6: LTG | M6: 13A | N6: 13A | O6: 15A | P6: WH | Q6: HD | R6: FCU | S6: SPUR | T6: ISOL | U6: TOTAL
I7: 1 | J7: 2 | K7: 3 | L7: 705 | M7: SO | N7: TSO | O7: SO | W7: R | X7: Y | Y7: B
L8: 42 | M8: 200 | N8: 400
A9: 40A TPN ISOLATOR | B9: 40A 100mA 4P | C9: 1 | D9: R1 | E9: 10 | F9: 2.5 | G9: 2.5 | H9: RECEPTION (LGT-603,703) | I9: 1 | J9: 18 | V9: 50 | W9: =(V9*J9)+(V9*I9) -> 950
C10: 2 | D10: Y1 | E10: 10 | F10: 2.5 | G10: 2.5 | H10: RETAIL AND TESTING (LGT-703,601,101) | I10: 9 | J10: 1 | K10: 10 | V10: 50,20,10 | X10: =(50*I10)+(20*J10)+(10*K10) -> 570
C11: 3 | D11: B1 | E11: 10 | F11: 2.5 | G11: 2.5 | H11: DISPLAY & WAITING (LGT-101,703) | I11: 16 | J11: 22 | V11: 15,50 | Y11: =(15*I11)+(50*J11) -> 1340
C12: 4 | D12: R2 | E12: 10 | F12: 2.5 | G12: 2.5 | H12: BY KITCHEN SPECIALIST | L12: 3 | W12: =L12*L8 -> 126
C13: 5 | D13: Y2 | E13: 10 | F13: 2.5 | G13: 2.5 | H13: RETAIL (LGT-704 | J13: 2 | V13: 20 | X13: =(20*I13)+(100*J13) -> 200
C14: 6 | D14: B2 | E14: 10 | F14: 2.5 | G14: 2.5 | H14: OUTDOOR BAR | I14: 7 | V14: 15 | Y14: =V14*I14 -> 105
B15: 40A 30mA 4P | C15: 7 | D15: R3 | E15: 20 | F15: 4 | G15: 4 | H15: RECEPTIOIN | M15: 1 | N15: 2 | W15: =SUM(M15*M8,N15*N8) -> 1000
C16: 8 | D16: Y3 | E16: 20 | F16: 4 | G16: 4 | H16: RECEPTION | M16: 1 | N16: 2 | X16: =SUM(M16*M8,N16*N8) -> 1000
C17: 9 | D17: B3 | E17: 32 | F17: 4 | G17: 4 | H17: WAITING AND CONSULTATION AREA | N17: 4 | Y17: =N17*N8 -> 1600 | Z17: Ring
C18: 10 | D18: R4 | E18: 20 | F18: 4 | G18: 4 | H18: WAITING AND CONSULTATION AREA | M18: 2 | W18: =M18*M8 -> 400
C19: 11 | D19: Y4 | E19: 20 | F19: 4 | G19: 4 | H19: BY KITCHEN SPECIALIST | M19: 1 | N19: 1 | X19: =SUM(M19*M8,N19*N8) -> 600
C20: 12 | D20: B4 | Y20: =N20*N8 -> 0
B21: 40A 30mA 4P | C21: 13 | D21: R5 | W21: =N21*N8 -> 0
C22: 14 | D22: Y5 | X22: =N22*N8 -> 0
C23: 15 | D23: B5 | E23: 20 | F23: 4 | G23: 4 | H23: OUTDOOR BAR | N23: 1 | Y23: =N23*N8 -> 400
C24: 16 | D24: R6 | W24: =V24*T24 -> 0
C25: 17 | D25: Y6 | X25: =V25*T25 -> 0
C26: 18 | D26: B6 | Y26: =V26*T26 -> 0
B27: 40A 30mA 4P | C27: 19 | D27: R7 | W27: =V27*T27 -> 0
C28: 20 | D28: Y7 | X28: 0
C29: 21 | D29: B7 | Y29: 0
C30: 22 | D30: R8 | W30: =V30*T30 -> 0
C31: 23 | D31: Y8 | X31: 0
C32: 24 | D32: B8 | Y32: 0
S33: TOTAL CONNECTED LOAD | W33: =SUM(W9:W32) -> 2476 | X33: =SUM(X9:X32) -> 2370 | Y33: =SUM(Y9:Y32) -> 3445 | Z33: =SUM(W33:Y33) -> 8291
S34: TOTAL CONNECTED LOAD (PF=0.8) | W34: =W33/0.8 -> 3095 | X34: =X33/0.8 -> 2962.5 | Y34: =Y33/0.8 -> 4306.25 | Z34: =SUM(W34:Y34) -> 10363.75
S35: DIVERSITY FACTOR | W35: 0.7
S36: TOTAL DIVERSITY LOAD | W36: =(W35*Z34)/1000 -> 7.254625 | Y36: KW
A37: CABLE SIZE : | B37: 4C 10 mm² Cu/XLPE/SWA/PVC + 1C 10 mm² Cu/PVC ECC
A38: W/H:WATER HEATER , WM: WASHING MACHINE, FCU - FAN COIL UNIT, H/D- HAND DRYER
